Workbook
Name POLIWAG: 'Localizações'!$A$14
Name figh: Search!$A$1
Name blastoise: 'Localizações'!$A$377:$A$387
Name vaporeon: #REF!
Name slowking: #REF!
Name StarObjetivo: 'Star Level'!$A$15:$E$15
Name brown: Search!$A$4:$A$1000
Name rhydon: 'Localizações'!$A$2
Name mouse: Search!$2:$2
Name charmander: Search!$A$2:$A$3
Name pinsir: 'Localizações'!$C$128
Name miss: #REF!
Name forretres: #REF!
Name Typhlosion: 'Localizações'!$B$392
Name rampardos: 'Localizações'!$A$1
Name arca: 'Localizações'!$E$14:$E$1000
Name ursarin: 'Localizações'!$E$2:$E$13
Name hitmontop: 'Localizações'!$C$274
Name fire: #REF!
Name onix: 'Localizações'!$A:$A
Name Grass: 'Tier List'!$C:$C
Name sky: Brokes!$A$1
Name seal: 'Localizações'!$C$1

Sheet Drops
A1: =IFERROR(__xludf.DUMMYFUNCTION("IMPORTRANGE(""Https://docs.google.com/spreadsheets/d/1ID3qu1P4Zey82OSLntg4O0xoZlY1hGK58tte0D_Cv_s/edit?gid=709790984#gid=709790984"", ""Drops!A1:K1600"")"),"Pokemon") -> Pokemon | B1: =IFERROR(__xludf.DUMMYFUNCTION("""COMPUTED_VALUE"""),"DROPS") -> DROPS
A2: =IFERROR(__xludf.DUMMYFUNCTION("""COMPUTED_VALUE"""),"Bulbasaur") -> Bulbasaur | B2: =IFERROR(__xludf.DUMMYFUNCTION("""COMPUTED_VALUE"""),"seed") -> seed | C2: =IFERROR(__xludf.DUMMYFUNCTION("""COMPUTED_VALUE"""),"bottle of poison") -> bottle of poison | D2: =IFERROR(__xludf.DUMMYFUNCTION("""COMPUTED_VALUE"""),"bulb") -> bulb
A3: =IFERROR(__xludf.DUMMYFUNCTION("""COMPUTED_VALUE"""),"Shiny Bulbasaur") -> Shiny Bulbasaur | B3: =IFERROR(__xludf.DUMMYFUNCTION("""COMPUTED_VALUE"""),"seed") -> seed | C3: =IFERROR(__xludf.DUMMYFUNCTION("""COMPUTED_VALUE"""),"bottle of poison") -> bottle of poison | D3: =IFERROR(__xludf.DUMMYFUNCTION("""COMPUTED_VALUE"""),"brown bulb") -> brown bulb | E3: =IFERROR(__xludf.DUMMYFUNCTION("""COMPUTED_VALUE"""),"leaf stone") -> leaf stone | F3: =IFERROR(__xludf.DUMMYFUNCTION("""COMPUTED_VALUE"""),"venom stone") -> venom stone | G3: =IFERROR(__xludf.DUMMYFUNCTION("""COMPUTED_VALUE"""),"simple grass orb") -> simple grass orb
A4: =IFERROR(__xludf.DUMMYFUNCTION("""COMPUTED_VALUE"""),"Ivysaur") -> Ivysaur | B4: =IFERROR(__xludf.DUMMYFUNCTION("""COMPUTED_VALUE"""),"seed") -> seed | C4: =IFERROR(__xludf.DUMMYFUNCTION("""COMPUTED_VALUE"""),"bottle of poison") -> bottle of poison | D4: =IFERROR(__xludf.DUMMYFUNCTION("""COMPUTED_VALUE"""),"leaf") -> leaf | E4: =IFERROR(__xludf.DUMMYFUNCTION("""COMPUTED_VALUE"""),"leaf stone") -> leaf stone | F4: =IFERROR(__xludf.DUMMYFUNCTION("""COMPUTED_VALUE"""),"venom stone") -> venom stone
A5: =IFERROR(__xludf.DUMMYFUNCTION("""COMPUTED_VALUE"""),"Shiny Ivysaur") -> Shiny Ivysaur | B5: =IFERROR(__xludf.DUMMYFUNCTION("""COMPUTED_VALUE"""),"seed") -> seed | C5: =IFERROR(__xludf.DUMMYFUNCTION("""COMPUTED_VALUE"""),"bottle of poison") -> bottle of poison | D5: =IFERROR(__xludf.DUMMYFUNCTION("""COMPUTED_VALUE"""),"purple leaf") -> purple leaf | E5: =IFERROR(__xludf.DUMMYFUNCTION("""COMPUTED_VALUE"""),"leaf stone") -> leaf stone | F5: =IFERROR(__xludf.DUMMYFUNCTION("""COMPUTED_VALUE"""),"venom stone") -> venom stone | G5: =IFERROR(__xludf.DUMMYFUNCTION("""COMPUTED_VALUE"""),"arcane grass orb") -> arcane grass orb
A6: =IFERROR(__xludf.DUMMYFUNCTION("""COMPUTED_VALUE"""),"Venusaur") -> Venusaur | B6: =IFERROR(__xludf.DUMMYFUNCTION("""COMPUTED_VALUE"""),"seed") -> seed | C6: =IFERROR(__xludf.DUMMYFUNCTION("""COMPUTED_VALUE"""),"bottle of poison") -> bottle of poison | D6: =IFERROR(__xludf.DUMMYFUNCTION("""COMPUTED_VALUE"""),"red petal") -> red petal | E6: =IFERROR(__xludf.DUMMYFUNCTION("""COMPUTED_VALUE"""),"leaf stone") -> leaf stone | F6: =IFERROR(__xludf.DUMMYFUNCTION("""COMPUTED_VALUE"""),"venom stone") -> venom stone
A7: =IFERROR(__xludf.DUMMYFUNCTION("""COMPUTED_VALUE"""),"Shiny Venusaur") -> Shiny Venusaur | B7: =IFERROR(__xludf.DUMMYFUNCTION("""COMPUTED_VALUE"""),"seed") -> seed | C7: =IFERROR(__xludf.DUMMYFUNCTION("""COMPUTED_VALUE"""),"bottle of poison") -> bottle of poison | D7: =IFERROR(__xludf.DUMMYFUNCTION("""COMPUTED_VALUE"""),"brown petal") -> brown petal | E7: =IFERROR(__xludf.DUMMYFUNCTION("""COMPUTED_VALUE"""),"leaf stone") -> leaf stone | F7: =IFERROR(__xludf.DUMMYFUNCTION("""COMPUTED_VALUE"""),"venom stone") -> venom stone | G7: =IFERROR(__xludf.DUMMYFUNCTION("""COMPUTED_VALUE"""),"mythic grass orb") -> mythic grass orb
A8: =IFERROR(__xludf.DUMMYFUNCTION("""COMPUTED_VALUE"""),"Charmander") -> Charmander | B8: =IFERROR(__xludf.DUMMYFUNCTION("""COMPUTED_VALUE"""),"essence of fire") -> essence of fire | C8: =IFERROR(__xludf.DUMMYFUNCTION("""COMPUTED_VALUE"""),"fire tail") -> fire tail
A9: =IFERROR(__xludf.DUMMYFUNCTION("""COMPUTED_VALUE"""),"Shiny Charmander") -> Shiny Charmander | B9: =IFERROR(__xludf.DUMMYFUNCTION("""COMPUTED_VALUE"""),"essence of fire") -> essence of fire | C9: =IFERROR(__xludf.DUMMYFUNCTION("""COMPUTED_VALUE"""),"black tail") -> black tail | D9: =IFERROR(__xludf.DUMMYFUNCTION("""COMPUTED_VALUE"""),"fire stone") -> fire stone | E9: =IFERROR(__xludf.DUMMYFUNCTION("""COMPUTED_VALUE"""),"simple fire orb") -> simple fire orb
A10: =IFERROR(__xludf.DUMMYFUNCTION("""COMPUTED_VALUE"""),"Charmelion") -> Charmelion | B10: =IFERROR(__xludf.DUMMYFUNCTION("""COMPUTED_VALUE"""),"essence of fire") -> essence of fire | C10: =IFERROR(__xludf.DUMMYFUNCTION("""COMPUTED_VALUE"""),"lizard tail") -> lizard tail | D10: =IFERROR(__xludf.DUMMYFUNCTION("""COMPUTED_VALUE"""),"fire stone") -> fire stone
A11: =IFERROR(__xludf.DUMMYFUNCTION("""COMPUTED_VALUE"""),"Shiny Charmelion") -> Shiny Charmelion | B11: =IFERROR(__xludf.DUMMYFUNCTION("""COMPUTED_VALUE"""),"essence of fire") -> essence of fire | C11: =IFERROR(__xludf.DUMMYFUNCTION("""COMPUTED_VALUE"""),"black lizard tail") -> black lizard tail | D11: =IFERROR(__xludf.DUMMYFUNCTION("""COMPUTED_VALUE"""),"fire stone") -> fire stone | E11: =IFERROR(__xludf.DUMMYFUNCTION("""COMPUTED_VALUE"""),"arcane fire orb") -> arcane fire orb
A12: =IFERROR(__xludf.DUMMYFUNCTION("""COMPUTED_VALUE"""),"Charizard") -> Charizard | B12: =IFERROR(__xludf.DUMMYFUNCTION("""COMPUTED_VALUE"""),"essence of fire") -> essence of fire | C12: =IFERROR(__xludf.DUMMYFUNCTION("""COMPUTED_VALUE"""),"straw") -> straw | D12: =IFERROR(__xludf.DUMMYFUNCTION("""COMPUTED_VALUE"""),"fire wing") -> fire wing | E12: =IFERROR(__xludf.DUMMYFUNCTION("""COMPUTED_VALUE"""),"fire stone") -> fire stone | F12: =IFERROR(__xludf.DUMMYFUNCTION("""COMPUTED_VALUE"""),"feather stone") -> feather stone
A13: =IFERROR(__xludf.DUMMYFUNCTION("""COMPUTED_VALUE"""),"Shiny Charizard") -> Shiny Charizard | B13: =IFERROR(__xludf.DUMMYFUNCTION("""COMPUTED_VALUE"""),"essence of fire") -> essence of fire | C13: =IFERROR(__xludf.DUMMYFUNCTION("""COMPUTED_VALUE"""),"essence of fire") -> essence of fire | D13: =IFERROR(__xludf.DUMMYFUNCTION("""COMPUTED_VALUE"""),"straw") -> straw | E13: =IFERROR(__xludf.DUMMYFUNCTION("""COMPUTED_VALUE"""),"dark wing") -> dark wing | F13: =IFERROR(__xludf.DUMMYFUNCTION("""COMPUTED_VALUE"""),"fire stone") -> fire stone | G13: =IFERROR(__xludf.DUMMYFUNCTION("""COMPUTED_VALUE"""),"feather stone") -> feather stone | H13: =IFERROR(__xludf.DUMMYFUNCTION("""COMPUTED_VALUE"""),"mythic fire orb") -> mythic fire orb
A14: =IFERROR(__xludf.DUMMYFUNCTION("""COMPUTED_VALUE"""),"Squirtle") -> Squirtle | B14: =IFERROR(__xludf.DUMMYFUNCTION("""COMPUTED_VALUE"""),"water gem") -> water gem | C14: =IFERROR(__xludf.DUMMYFUNCTION("""COMPUTED_VALUE"""),"squirtle hull") -> squirtle hull
A15: =IFERROR(__xludf.DUMMYFUNCTION("""COMPUTED_VALUE"""),"Shiny Squirtle") -> Shiny Squirtle | B15: =IFERROR(__xludf.DUMMYFUNCTION("""COMPUTED_VALUE"""),"water gem") -> water gem | C15: =IFERROR(__xludf.DUMMYFUNCTION("""COMPUTED_VALUE"""),"cyan hull") -> cyan hull | D15: =IFERROR(__xludf.DUMMYFUNCTION("""COMPUTED_VALUE"""),"water stone") -> water stone | E15: =IFERROR(__xludf.DUMMYFUNCTION("""COMPUTED_VALUE"""),"simple water orb") -> simple water orb
A16: =IFERROR(__xludf.DUMMYFUNCTION("""COMPUTED_VALUE"""),"Wartortle") -> Wartortle | B16: =IFERROR(__xludf.DUMMYFUNCTION("""COMPUTED_VALUE"""),"water gem") -> water gem | C16: =IFERROR(__xludf.DUMMYFUNCTION("""COMPUTED_VALUE"""),"water gem") -> water gem | D16: =IFERROR(__xludf.DUMMYFUNCTION("""COMPUTED_VALUE"""),"wartortle ear") -> wartortle ear | E16: =IFERROR(__xludf.DUMMYFUNCTION("""COMPUTED_VALUE"""),"water stone") -> water stone
A17: =IFERROR(__xludf.DUMMYFUNCTION("""COMPUTED_VALUE"""),"Shiny Wartortle") -> Shiny Wartortle | B17: =IFERROR(__xludf.DUMMYFUNCTION("""COMPUTED_VALUE"""),"water gem") -> water gem | C17: =IFERROR(__xludf.DUMMYFUNCTION("""COMPUTED_VALUE"""),"water gem") -> water gem | D17: =IFERROR(__xludf.DUMMYFUNCTION("""COMPUTED_VALUE"""),"cyan ear") -> cyan ear | E17: =IFERROR(__xludf.DUMMYFUNCTION("""COMPUTED_VALUE"""),"water stone") -> water stone | F17: =IFERROR(__xludf.DUMMYFUNCTION("""COMPUTED_VALUE"""),"arcane water orb") -> arcane water orb
A18: =IFERROR(__xludf.DUMMYFUNCTION("""COMPUTED_VALUE"""),"Blastoise") -> Blastoise | B18: =IFERROR(__xludf.DUMMYFUNCTION("""COMPUTED_VALUE"""),"water gem") -> water gem | C18: =IFERROR(__xludf.DUMMYFUNCTION("""COMPUTED_VALUE"""),"water cannon") -> water cannon | D18: =IFERROR(__xludf.DUMMYFUNCTION("""COMPUTED_VALUE"""),"water stone") -> water stone
A19: =IFERROR(__xludf.DUMMYFUNCTION("""COMPUTED_VALUE"""),"Shiny Blastoise") -> Shiny Blastoise | B19: =IFERROR(__xludf.DUMMYFUNCTION("""COMPUTED_VALUE"""),"water gem") -> water gem | C19: =IFERROR(__xludf.DUMMYFUNCTION("""COMPUTED_VALUE"""),"giant water cannon") -> giant water cannon | D19: =IFERROR(__xludf.DUMMYFUNCTION("""COMPUTED_VALUE"""),"water stone") -> water stone | E19: =IFERROR(__xludf.DUMMYFUNCTION("""COMPUTED_VALUE"""),"mythic water orb") -> mythic water orb
A20: =IFERROR(__xludf.DUMMYFUNCTION("""COMPUTED_VALUE"""),"Caterpie") -> Caterpie | B20: =IFERROR(__xludf.DUMMYFUNCTION("""COMPUTED_VALUE"""),"bug gosme") -> bug gosme | C20: =IFERROR(__xludf.DUMMYFUNCTION("""COMPUTED_VALUE"""),"caterpie antenna") -> caterpie antenna
A21: =IFERROR(__xludf.DUMMYFUNCTION("""COMPUTED_VALUE"""),"Shiny Caterpie") -> Shiny Caterpie | B21: =IFERROR(__xludf.DUMMYFUNCTION("""COMPUTED_VALUE"""),"bug gosme") -> bug gosme | C21: =IFERROR(__xludf.DUMMYFUNCTION("""COMPUTED_VALUE"""),"sparkle antenna") -> sparkle antenna | D21: =IFERROR(__xludf.DUMMYFUNCTION("""COMPUTED_VALUE"""),"simple bug orb") -> simple bug orb
A22: =IFERROR(__xludf.DUMMYFUNCTION("""COMPUTED_VALUE"""),"Metapod") -> Metapod | B22: =IFERROR(__xludf.DUMMYFUNCTION("""COMPUTED_VALUE"""),"bug gosme") -> bug gosme | C22: =IFERROR(__xludf.DUMMYFUNCTION("""COMPUTED_VALUE"""),"piece of cocoon") -> piece of cocoon | D22: =IFERROR(__xludf.DUMMYFUNCTION("""COMPUTED_VALUE"""),"cocoon stone") -> cocoon stone
A23: =IFERROR(__xludf.DUMMYFUNCTION("""COMPUTED_VALUE"""),"Shiny Metapod") -> Shiny Metapod | B23: =IFERROR(__xludf.DUMMYFUNCTION("""COMPUTED_VALUE"""),"bug gosme") -> bug gosme | C23: =IFERROR(__xludf.DUMMYFUNCTION("""COMPUTED_VALUE"""),"red piece of cocoon") -> red piece of cocoon | D23: =IFERROR(__xludf.DUMMYFUNCTION("""COMPUTED_VALUE"""),"cocoon stone") -> cocoon stone | E23: =IFERROR(__xludf.DUMMYFUNCTION("""COMPUTED_VALUE"""),"simple bug orb") -> simple bug orb
A24: =IFERROR(__xludf.DUMMYFUNCTION("""COMPUTED_VALUE"""),"Butterfree") -> Butterfree | B24: =IFERROR(__xludf.DUMMYFUNCTION("""COMPUTED_VALUE"""),"bug gosme") -> bug gosme | C24: =IFERROR(__xludf.DUMMYFUNCTION("""COMPUTED_VALUE"""),"straw") -> straw | D24: =IFERROR(__xludf.DUMMYFUNCTION("""COMPUTED_VALUE"""),"butterfree wing") -> butterfree wing | E24: =IFERROR(__xludf.DUMMYFUNCTION("""COMPUTED_VALUE"""),"cocoon stone") -> cocoon stone | F24: =IFERROR(__xludf.DUMMYFUNCTION("""COMPUTED_VALUE"""),"feather stone") -> feather stone
A25: =IFERROR(__xludf.DUMMYFUNCTION("""COMPUTED_VALUE"""),"Shiny Butterfree") -> Shiny Butterfree | B25: =IFERROR(__xludf.DUMMYFUNCTION("""COMPUTED_VALUE"""),"bug gosme") -> bug gosme | C25: =IFERROR(__xludf.DUMMYFUNCTION("""COMPUTED_VALUE"""),"straw") -> straw | D25: =IFERROR(__xludf.DUMMYFUNCTION("""COMPUTED_VALUE"""),"pink wing") -> pink wing | E25: =IFERROR(__xludf.DUMMYFUNCTION("""COMPUTED_VALUE"""),"cocoon stone") -> cocoon stone | F25: =IFERROR(__xludf.DUMMYFUNCTION("""COMPUTED_VALUE"""),"feather stone") -> feather stone | G25: =IFERROR(__xludf.DUMMYFUNCTION("""COMPUTED_VALUE"""),"arcane bug orb") -> arcane bug orb
A26: =IFERROR(__xludf.DUMMYFUNCTION("""COMPUTED_VALUE"""),"Weedle") -> Weedle | B26: =IFERROR(__xludf.DUMMYFUNCTION("""COMPUTED_VALUE"""),"bug gosme") -> bug gosme | C26: =IFERROR(__xludf.DUMMYFUNCTION("""COMPUTED_VALUE"""),"bottle of poison") -> bottle of poison | D26: =IFERROR(__xludf.DUMMYFUNCTION("""COMPUTED_VALUE"""),"poison sting") -> poison sting
A27: =IFERROR(__xludf.DUMMYFUNCTION("""COMPUTED_VALUE"""),"Shiny Weedle") -> Shiny Weedle | B27: =IFERROR(__xludf.DUMMYFUNCTION("""COMPUTED_VALUE"""),"bug gosme") -> bug gosme | C27: =IFERROR(__xludf.DUMMYFUNCTION("""COMPUTED_VALUE"""),"bottle of poison") -> bottle of poison | D27: =IFERROR(__xludf.DUMMYFUNCTION("""COMPUTED_VALUE"""),"yellow sting") -> yellow sting | E27: =IFERROR(__xludf.DUMMYFUNCTION("""COMPUTED_VALUE"""),"simple bug orb") -> simple bug orb
A28: =IFERROR(__xludf.DUMMYFUNCTION("""COMPUTED_VALUE"""),"Kakuna") -> Kakuna | B28: =IFERROR(__xludf.DUMMYFUNCTION("""COMPUTED_VALUE"""),"bug gosme") -> bug gosme | C28: =IFERROR(__xludf.DUMMYFUNCTION("""COMPUTED_VALUE"""),"bottle of poison") -> bottle of poison | D28: =IFERROR(__xludf.DUMMYFUNCTION("""COMPUTED_VALUE"""),"yellow cocoon") -> yellow cocoon | E28: =IFERROR(__xludf.DUMMYFUNCTION("""COMPUTED_VALUE"""),"cocoon stone") -> cocoon stone
A29: =IFERROR(__xludf.DUMMYFUNCTION("""COMPUTED_VALUE"""),"Shiny Kakuna") -> Shiny Kakuna | B29: =IFERROR(__xludf.DUMMYFUNCTION("""COMPUTED_VALUE"""),"bug gosme") -> bug gosme | C29: =IFERROR(__xludf.DUMMYFUNCTION("""COMPUTED_VALUE"""),"bottle of poison") -> bottle of poison | D29: =IFERROR(__xludf.DUMMYFUNCTION("""COMPUTED_VALUE"""),"red cocoon") -> red cocoon | E29: =IFERROR(__xludf.DUMMYFUNCTION("""COMPUTED_VALUE"""),"cocoon stone") -> cocoon stone | F29: =IFERROR(__xludf.DUMMYFUNCTION("""COMPUTED_VALUE"""),"venom stone") -> venom stone | G29: =IFERROR(__xludf.DUMMYFUNCTION("""COMPUTED_VALUE"""),"simple bug orb") -> simple bug orb
A30: =IFERROR(__xludf.DUMMYFUNCTION("""COMPUTED_VALUE"""),"Beedrill") -> Beedrill | B30: =IFERROR(__xludf.DUMMYFUNCTION("""COMPUTED_VALUE"""),"bug gosme") -> bug gosme | C30: =IFERROR(__xludf.DUMMYFUNCTION("""COMPUTED_VALUE"""),"bottle of poison") -> bottle of poison | D30: =IFERROR(__xludf.DUMMYFUNCTION("""COMPUTED_VALUE"""),"bee sting") -> bee sting | E30: =IFERROR(__xludf.DUMMYFUNCTION("""COMPUTED_VALUE"""),"cocoon stone") -> cocoon stone | F30: =IFERROR(__xludf.DUMMYFUNCTION("""COMPUTED_VALUE"""),"venom stone") -> venom stone
A31: =IFERROR(__xludf.DUMMYFUNCTION("""COMPUTED_VALUE"""),"Shiny Beedrill") -> Shiny Beedrill | B31: =IFERROR(__xludf.DUMMYFUNCTION("""COMPUTED_VALUE"""),"bug gosme") -> bug gosme | C31: =IFERROR(__xludf.DUMMYFUNCTION("""COMPUTED_VALUE"""),"bottle of poison") -> bottle of poison | D31: =IFERROR(__xludf.DUMMYFUNCTION("""COMPUTED_VALUE"""),"red bee sting") -> red bee sting | E31: =IFERROR(__xludf.DUMMYFUNCTION("""COMPUTED_VALUE"""),"cocoon stone") -> cocoon stone | F31: =IFERROR(__xludf.DUMMYFUNCTION("""COMPUTED_VALUE"""),"venom stone") -> venom stone | G31: =IFERROR(__xludf.DUMMYFUNCTION("""COMPUTED_VALUE"""),"arcane bug orb") -> arcane bug orb
A32: =IFERROR(__xludf.DUMMYFUNCTION("""COMPUTED_VALUE"""),"Pidgey") -> Pidgey | B32: =IFERROR(__xludf.DUMMYFUNCTION("""COMPUTED_VALUE"""),"rubber ball") -> rubber ball | C32: =IFERROR(__xludf.DUMMYFUNCTION("""COMPUTED_VALUE"""),"straw") -> straw | D32: =IFERROR(__xludf.DUMMYFUNCTION("""COMPUTED_VALUE"""),"bird crest") -> bird crest
A33: =IFERROR(__xludf.DUMMYFUNCTION("""COMPUTED_VALUE"""),"Shiny Pidgey") -> Shiny Pidgey | B33: =IFERROR(__xludf.DUMMYFUNCTION("""COMPUTED_VALUE"""),"rubber ball") -> rubber ball | C33: =IFERROR(__xludf.DUMMYFUNCTION("""COMPUTED_VALUE"""),"straw") -> straw | D33: =IFERROR(__xludf.DUMMYFUNCTION("""COMPUTED_VALUE"""),"yellow bird crest") -> yellow bird crest | E33: =IFERROR(__xludf.DUMMYFUNCTION("""COMPUTED_VALUE"""),"simple flying orb") -> simple flying orb
A34: =IFERROR(__xludf.DUMMYFUNCTION("""COMPUTED_VALUE"""),"Pidgeotto") -> Pidgeotto | B34: =IFERROR(__xludf.DUMMYFUNCTION("""COMPUTED_VALUE"""),"rubber ball") -> rubber ball | C34: =IFERROR(__xludf.DUMMYFUNCTION("""COMPUTED_VALUE"""),"straw") -> straw | D34: =IFERROR(__xludf.DUMMYFUNCTION("""COMPUTED_VALUE"""),"bird tail") -> bird tail | E34: =IFERROR(__xludf.DUMMYFUNCTION("""COMPUTED_VALUE"""),"heart stone") -> heart stone | F34: =IFERROR(__xludf.DUMMYFUNCTION("""COMPUTED_VALUE"""),"feather stone") -> feather stone
A35: =IFERROR(__xludf.DUMMYFUNCTION("""COMPUTED_VALUE"""),"Shiny Pidgeotto") -> Shiny Pidgeotto | B35: =IFERROR(__xludf.DUMMYFUNCTION("""COMPUTED_VALUE"""),"rubber ball") -> rubber ball | C35: =IFERROR(__xludf.DUMMYFUNCTION("""COMPUTED_VALUE"""),"straw") -> straw | D35: =IFERROR(__xludf.DUMMYFUNCTION("""COMPUTED_VALUE"""),"two-colored tail") -> two-colored tail | E35: =IFERROR(__xludf.DUMMYFUNCTION("""COMPUTED_VALUE"""),"heart stone") -> heart stone | F35: =IFERROR(__xludf.DUMMYFUNCTION("""COMPUTED_VALUE"""),"feather stone") -> feather stone | G35: =IFERROR(__xludf.DUMMYFUNCTION("""COMPUTED_VALUE"""),"arcane flying orb") -> arcane flying orb
A36: =IFERROR(__xludf.DUMMYFUNCTION("""COMPUTED_VALUE"""),"Pidgeot") -> Pidgeot | B36: =IFERROR(__xludf.DUMMYFUNCTION("""COMPUTED_VALUE"""),"rubber ball") -> rubber ball | C36: =IFERROR(__xludf.DUMMYFUNCTION("""COMPUTED_VALUE"""),"straw") -> straw | D36: =IFERROR(__xludf.DUMMYFUNCTION("""COMPUTED_VALUE"""),"bird beak") -> bird beak | E36: =IFERROR(__xludf.DUMMYFUNCTION("""COMPUTED_VALUE"""),"heart stone") -> heart stone | F36: =IFERROR(__xludf.DUMMYFUNCTION("""COMPUTED_VALUE"""),"feather stone") -> feather stone
A37: =IFERROR(__xludf.DUMMYFUNCTION("""COMPUTED_VALUE"""),"Shiny Pidgeot") -> Shiny Pidgeot | B37: =IFERROR(__xludf.DUMMYFUNCTION("""COMPUTED_VALUE"""),"rubber ball") -> rubber ball | C37: =IFERROR(__xludf.DUMMYFUNCTION("""COMPUTED_VALUE"""),"straw") -> straw | D37: =IFERROR(__xludf.DUMMYFUNCTION("""COMPUTED_VALUE"""),"two-colored crest") -> two-colored crest | E37: =IFERROR(__xludf.DUMMYFUNCTION("""COMPUTED_VALUE"""),"heart stone") -> heart stone | F37: =IFERROR(__xludf.DUMMYFUNCTION("""COMPUTED_VALUE"""),"feather stone") -> feather stone | G37: =IFERROR(__xludf.DUMMYFUNCTION("""COMPUTED_VALUE"""),"mythic flying orb") -> mythic flying orb
A38: =IFERROR(__xludf.DUMMYFUNCTION("""COMPUTED_VALUE"""),"Rattata") -> Rattata | B38: =IFERROR(__xludf.DUMMYFUNCTION("""COMPUTED_VALUE"""),"rubber ball") -> rubber ball | C38: =IFERROR(__xludf.DUMMYFUNCTION("""COMPUTED_VALUE"""),"mouse tail") -> mouse tail
A39: =IFERROR(__xludf.DUMMYFUNCTION("""COMPUTED_VALUE"""),"Shiny Rattata") -> Shiny Rattata | B39: =IFERROR(__xludf.DUMMYFUNCTION("""COMPUTED_VALUE"""),"rubber ball") -> rubber ball | C39: =IFERROR(__xludf.DUMMYFUNCTION("""COMPUTED_VALUE"""),"blue Mouse Tail") -> blue Mouse Tail | D39: =IFERROR(__xludf.DUMMYFUNCTION("""COMPUTED_VALUE"""),"simple normal orb") -> simple normal orb
A40: =IFERROR(__xludf.DUMMYFUNCTION("""COMPUTED_VALUE"""),"Raticate") -> Raticate | B40: =IFERROR(__xludf.DUMMYFUNCTION("""COMPUTED_VALUE"""),"rubber ball") -> rubber ball | C40: =IFERROR(__xludf.DUMMYFUNCTION("""COMPUTED_VALUE"""),"rat ear") -> rat ear | D40: =IFERROR(__xludf.DUMMYFUNCTION("""COMPUTED_VALUE"""),"heart stone") -> heart stone
...

Sheet Index
B8: =HYPERLINK("https://docs.google.com/spreadsheets/d/1GCH3PmFKQrBj7AA51hgqfg6Q2SrvNgrNlxgIidVeTMU/edit?pli=1&gid=1112155848#gid=1112155848",IMAGE("https://i.imgur.com/uwh7mPY.png")) | F8: =HYPERLINK("https://docs.google.com/spreadsheets/d/1GCH3PmFKQrBj7AA51hgqfg6Q2SrvNgrNlxgIidVeTMU/edit?pli=1&gid=1881536412#gid=1881536412",IMAGE("https://i.imgur.com/pjoG0fa.png")) | J8: =HYPERLINK("https://docs.google.com/spreadsheets/d/1GCH3PmFKQrBj7AA51hgqfg6Q2SrvNgrNlxgIidVeTMU/edit?pli=1&gid=622619474#gid=622619474",IMAGE("https://i.imgur.com/EDc1VZz.png"))
J13: =HYPERLINK("https://docs.google.com/spreadsheets/d/1GCH3PmFKQrBj7AA51hgqfg6Q2SrvNgrNlxgIidVeTMU/edit?pli=1&gid=1112155848#gid=1112155848",IMAGE("https://imgur.com/a/FhRl6MG"))
B14: =HYPERLINK("https://docs.google.com/spreadsheets/d/1GCH3PmFKQrBj7AA51hgqfg6Q2SrvNgrNlxgIidVeTMU/edit?pli=1&gid=751365694#gid=751365694",IMAGE("https://i.imgur.com/mQmfFCu.png")) | F14: =HYPERLINK("https://docs.google.com/spreadsheets/d/1GCH3PmFKQrBj7AA51hgqfg6Q2SrvNgrNlxgIidVeTMU/edit?pli=1&gid=1798431963#gid=1798431963",IMAGE("https://i.imgur.com/u9P90MY.png"))
B20: =HYPERLINK("https://docs.google.com/spreadsheets/d/1GCH3PmFKQrBj7AA51hgqfg6Q2SrvNgrNlxgIidVeTMU/edit?pli=1&gid=1684775291#gid=1684775291",IMAGE("https://i.imgur.com/h5PYsbu.png")) | F20: =HYPERLINK("https://docs.google.com/spreadsheets/d/1GCH3PmFKQrBj7AA51hgqfg6Q2SrvNgrNlxgIidVeTMU/edit?pli=1&gid=1372498596#gid=1372498596",IMAGE("https://i.imgur.com/TIQizsS.png"))

Sheet FAQ
A1: star | B1: Star Ascension: wiki.pokealliance.com/sistemas/star-machine / Calculadora de custos pra estrelar: tinyurl.com/planilha-pka-star A máquina fica subindo uma escada no TC | C1: ",
A2: boost | B2: Boost Pokémon: wiki.pokealliance.com/guias/boost_stone A máquina de boost fica no meio do TC, do lado direito | C2: ",
A3: up | B3: Guia de up até o lvl 150: https://discord.com/channels/1159230367803392022/1308522087517782047 / Primeiros passos: wiki.pokealliance.com/guias/primeiros-passos | C3: ",
A4: fly | B4: Order no seu pé pra montar no fly. Subir e descer configura as hotkeys no Ctrl K -> Movements -> Fly Up e Fly Down. Se quiser tirar os botões que aparecem na tela, é em Config -> Game -> Show Fly Up/Down buttons | C4: ",
A5: ilhas laranja | B5: Ilhas laranja (lvl150+): Fala com o Captain Frederic, na praia sul de Cianwood, e depois pega a chave escondida atrás do coqueiro (imgur.com/a/uu36dVY), e entrega a chave para o capitão. Depois só voar pra ilha que precisa ir | C5: ",
A6: mapa | B6: Pra liberar o mapa completo: tinyurl.com/discord-pka-mapa Fecha o jogo, e importa o arquivo pelo launcher: imgur.com/a/FzbjhL0 | C6: ",
A7: ditto | B7: Pra fazer o shiny Ditto: wiki.pokealliance.com/quests/quests-principais#dr-oliveira-e-shiny-ditto O NPC Fica no lab de Pallet | C7: ",
A8: combo autocombo | B8: Autocombo: Botão direito nas skills -> Open Auto Combo. Arrasta a skills pra baixo na ordem que quiser. Fecha a interface, botão direito no terceiro botão da action bar (o monstrinho) e seta a hotkey. imgur.com/6xFdECI | C8: ",
A9: pesca | B9: Pra pescar, tem que procurar os fishing spots (uns peixes na água) direita ou sul de Saffron. Quando achar, aperta Ctrl Z e clica nele. Pescar só upa a skill de pesca, não da xp pro personagem, e nem vem muito shiny | C9: ",
A10: fundir | B10: Fundir helds: wiki.pokealliance.com/sistemas/helds#fusao-de-helds A máquina fica no meio do TC | C10: ",
A11: trocar | B11: Trocar tokens por helds: youtu.be/Bvq8_LrDuXo?t=50 | C11: ",
A12: cupom | B12: Cupons: Biskella, Anunaki, Bandicot, Lemes, Safnaw, Loxas, Lele, Emprego, Twooplayerss, Kaka, Lixito | C12: ",
... A100: ping | B100: Nâo tem como ver o ping dentro do jogo. O mais próximo é mandar um "ping pokealliance.com" no cmd | C100: ",
B101: 100k cargas premium upam 1 pokemon do lvl 0 até lvl 23 + 30% | C101: ",
A102: 150 | B102: Depois do lvl 150 vc upa em qualquer wildscape (hunt com caveira) que vc tenha pokes pra caçar: tinyurl.com/planilha-pka-hunts | C102: ",
A103: tubos | B103: Tubos (Hunt lvl 350+): imgur.com/a/wFcUcVR | C103: ",
A104: python | B104: Fiz um scriptzinho em python onde eu aperto um atalho, digito uma palavra chave da pergunta, e ele ja traz a mensagem pro meu Ctrl C | C104: ",
A105: qwilfish | B105: NPC pra trocar o item do Qwilfish pelo shiny: imgur.com/a/fmnPze7 | C105: ",
A106: reinicia reabre | B106: Reabre o client, e força atualização pelo launcher, clicando na engrenagem em cima/direita -> Verificar atualizações | C106: ",
A107: package | B107: Usa um Package Kit no item pra tirar ele da house. Compra por 1k na NPC July na entrada do TC -> | C107: ",
A108: quest | B108: Quests principais: wiki.pokealliance.com/quests/quests-principais | C108: ",
A109: wiki | B109: Wiki oficial do PKA: wiki.pokealliance.com | C109: ",
A110: outland | B110: .h outland north/east/south | C110: ",
A111: depot | B111: Depot stash no TC, uma caixa azul perto da televisão | C111: ",
A112: autoloot | B112: autoloot é só pra vip. Se não for, aperta espaço perto dos corpos pra lootear. E se quiser trocar a hotkey, Ctrl K -> Others -> Auto Loot | C112: ",
A113: tracker rastreador | B113: Tracker de Linked/Pokelog: Ctrl T -> Pokelog -> Open Tracker / Tracker de Brokes: Ctrl T -> Pokemon Brokes -> Open Tracker. Clica na mira do lado do pokemon pra adicionar ele no tracker | C113: ",
A114: revendedor | B114: Revendedor oficial do PKA: curse.com.br/pokealliance | C114: ",
... A122: dailyguild | B122: Daily guild são 42 tasks por semana (7 diárias + 35 tickets). Mais detalhes: https://discord.com/channels/1159230367803392022/1159230368940032093/1536193255350345848 | C122: ",
A123: surf | B123: pra surfar é só andar em direção à água, tendo um poke pra fora que tenha surf
A124: ability habilidade | B124: pra saber se o pokemon tem fly, surf, dig... olha na Pokedex -> Info -> Field Abilities
A125: comandos | B125: wiki.pokealliance.com/guias/comandos-disponiveis
A126: ticket | B126: Pra abrir ticket, pokealliance.com/ faz o login e clica em "Tickets"
A127: instancia canal | B127: Pra saber se um poke tem instância, procura a foto dele no Ctrl Tab. Geralmente ta em uma das hunts dele. Vai até lá, clica na porta pra escolher o canal. Caveira vermelha = wildscape(Lvl 150+). Brotinho = hunt normal
A128: topmenu | B128: Passa o mouse no meio da tela em cima que vai aparecer o botão pra abrir o menu
A129: help | B129: deixa o chat de Help só pra dúvidas sobre o jogo, por favor. Se for bug, abre um ticket no site. Sugestão manda no #sugestões no discord. Resto manda no GC
A130: mc | B130: pode abrir 2 clients, mas tem restrições. Da uma lida no chat #regras no Discord
A131: calendario | B131: calendário premium vc consegue resgatar os dias anteriores pagando 100 online points pra cada dia
A132: critico critical | B132: o efeito que aparece às vezes quando joga a ball é o critical catch. Naquela ball, a chance é dobrada
A133: technological | B133: revive normal só funciona até o lvl 219. Max revive funciona a partir do lvl 220. Technological revive é o único que funciona nas hunts de rotação (Lvl 350+)
A134: trade | B134: pra dar trade, ctrl click no item -> Trade With, e clica na pessoa
...

Sheet Linked Tasks
A1: Qtd | B1: Pokemon | C1: Tipo de hunt | D1: Hunt | E1: Kills/h
A2: 30 | B2: Rattata | C2: Normal | D2: =IF(B2<>"", SWITCH(C2, "Wild", VLOOKUP(B2, 'Localizações'!$A$2:$D992, 2, FALSE), "Normal", VLOOKUP(B2, 'Localizações'!$A$2:$D992, 3, FALSE), "Hoenn", VLOOKUP(B2, 'Localizações'!$A$2:$D992, 4, FALSE), ""), "") -> https://imgur.com/a/ZyszZOZ | F2: Pra ver as tasks, aperta Ctrl L no jogo Completando uma task, libera a próxima Mais detalhes: https://discord.com/channels/1159230367803392022/1159230368940032093/1495879078094311494
A3: 30 | B3: Oddish | C3: Normal | D3: =IF(B3<>"", SWITCH(C3, "Wild", VLOOKUP(B3, 'Localizações'!$A$2:$D992, 2, FALSE), "Normal", VLOOKUP(B3, 'Localizações'!$A$2:$D992, 3, FALSE), "Hoenn", VLOOKUP(B3, 'Localizações'!$A$2:$D992, 4, FALSE), ""), "") -> https://imgur.com/a/2SuUURl
A4: 30 | B4: Geodude | C4: Normal | D4: =IF(B4<>"", SWITCH(C4, "Wild", VLOOKUP(B4, 'Localizações'!$A$2:$D992, 2, FALSE), "Normal", VLOOKUP(B4, 'Localizações'!$A$2:$D992, 3, FALSE), "Hoenn", VLOOKUP(B4, 'Localizações'!$A$2:$D992, 4, FALSE), ""), "") -> https://imgur.com/a/IhJ17iJ
A5: 60 | B5: Mankey | C5: Normal | D5: =IF(B5<>"", SWITCH(C5, "Wild", VLOOKUP(B5, 'Localizações'!$A$2:$D992, 2, FALSE), "Normal", VLOOKUP(B5, 'Localizações'!$A$2:$D992, 3, FALSE), "Hoenn", VLOOKUP(B5, 'Localizações'!$A$2:$D992, 4, FALSE), ""), "") -> https://imgur.com/a/4E7gOtq
A6: 60 | B6: Rhyhorn | C6: Normal | D6: =IF(B6<>"", SWITCH(C6, "Wild", VLOOKUP(B6, 'Localizações'!$A$2:$D992, 2, FALSE), "Normal", VLOOKUP(B6, 'Localizações'!$A$2:$D992, 3, FALSE), "Hoenn", VLOOKUP(B6, 'Localizações'!$A$2:$D992, 4, FALSE), ""), "") -> https://imgur.com/a/cPbYaoO
A7: 60 | B7: Gloom | C7: Normal | D7: =IF(B7<>"", SWITCH(C7, "Wild", VLOOKUP(B7, 'Localizações'!$A$2:$D992, 2, FALSE), "Normal", VLOOKUP(B7, 'Localizações'!$A$2:$D992, 3, FALSE), "Hoenn", VLOOKUP(B7, 'Localizações'!$A$2:$D992, 4, FALSE), ""), "") -> https://imgur.com/a/TaH2l6m
A8: 100 | B8: Graveler | C8: Normal | D8: =IF(B8<>"", SWITCH(C8, "Wild", VLOOKUP(B8, 'Localizações'!$A$2:$D992, 2, FALSE), "Normal", VLOOKUP(B8, 'Localizações'!$A$2:$D992, 3, FALSE), "Hoenn", VLOOKUP(B8, 'Localizações'!$A$2:$D992, 4, FALSE), ""), "") -> https://imgur.com/a/SHzJxH4
A9: 100 | B9: Golbat | C9: Normal | D9: =IF(B9<>"", SWITCH(C9, "Wild", VLOOKUP(B9, 'Localizações'!$A$2:$D992, 2, FALSE), "Normal", VLOOKUP(B9, 'Localizações'!$A$2:$D992, 3, FALSE), "Hoenn", VLOOKUP(B9, 'Localizações'!$A$2:$D992, 4, FALSE), ""), "") -> https://imgur.com/a/uvfPxaO
A10: 250 | B10: Tangela | C10: Normal | D10: =IF(B10<>"", SWITCH(C10, "Wild", VLOOKUP(B10, 'Localizações'!$A$2:$D992, 2, FALSE), "Normal", VLOOKUP(B10, 'Localizações'!$A$2:$D992, 3, FALSE), "Hoenn", VLOOKUP(B10, 'Localizações'!$A$2:$D992, 4, FALSE), ""), "") -> https://imgur.com/a/IZyOqys
A11: 250 | B11: Marowak | C11: Normal | D11: =IF(B11<>"", SWITCH(C11, "Wild", VLOOKUP(B11, 'Localizações'!$A$2:$D992, 2, FALSE), "Normal", VLOOKUP(B11, 'Localizações'!$A$2:$D992, 3, FALSE), "Hoenn", VLOOKUP(B11, 'Localizações'!$A$2:$D992, 4, FALSE), ""), "") -> https://imgur.com/a/VrqZwDG | E11: 2150
A12: 250 | B12: Electrode | C12: Normal | D12: =IF(B12<>"", SWITCH(C12, "Wild", VLOOKUP(B12, 'Localizações'!$A$2:$D992, 2, FALSE), "Normal", VLOOKUP(B12, 'Localizações'!$A$2:$D992, 3, FALSE), "Hoenn", VLOOKUP(B12, 'Localizações'!$A$2:$D992, 4, FALSE), ""), "") -> https://imgur.com/a/ZNQjOvj
A13: 400 | B13: Magneton | C13: Normal | D13: =IF(B13<>"", SWITCH(C13, "Wild", VLOOKUP(B13, 'Localizações'!$A$2:$D992, 2, FALSE), "Normal", VLOOKUP(B13, 'Localizações'!$A$2:$D992, 3, FALSE), "Hoenn", VLOOKUP(B13, 'Localizações'!$A$2:$D992, 4, FALSE), ""), "") -> https://imgur.com/a/ZNQjOvj
A14: 500 | B14: Fearow | C14: Normal | D14: =IF(B14<>"", SWITCH(C14, "Wild", VLOOKUP(B14, 'Localizações'!$A$2:$D992, 2, FALSE), "Normal", VLOOKUP(B14, 'Localizações'!$A$2:$D992, 3, FALSE), "Hoenn", VLOOKUP(B14, 'Localizações'!$A$2:$D992, 4, FALSE), ""), "") -> https://imgur.com/a/NVXqWOp
A15: 800 | B15: Venusaur | C15: Normal | D15: =IF(B15<>"", SWITCH(C15, "Wild", VLOOKUP(B15, 'Localizações'!$A$2:$D992, 2, FALSE), "Normal", VLOOKUP(B15, 'Localizações'!$A$2:$D992, 3, FALSE), "Hoenn", VLOOKUP(B15, 'Localizações'!$A$2:$D992, 4, FALSE), ""), "") -> https://imgur.com/a/zRcrSLP
A16: 800 | B16: Blastoise | C16: Normal | D16: =IF(B16<>"", SWITCH(C16, "Wild", VLOOKUP(B16, 'Localizações'!$A$2:$D992, 2, FALSE), "Normal", VLOOKUP(B16, 'Localizações'!$A$2:$D992, 3, FALSE), "Hoenn", VLOOKUP(B16, 'Localizações'!$A$2:$D992, 4, FALSE), ""), "") -> https://imgur.com/a/o6O5mnt | E16: 2900
A17: 800 | B17: Charizard | C17: Normal | D17: =IF(B17<>"", SWITCH(C17, "Wild", VLOOKUP(B17, 'Localizações'!$A$2:$D992, 2, FALSE), "Normal", VLOOKUP(B17, 'Localizações'!$A$2:$D992, 3, FALSE), "Hoenn", VLOOKUP(B17, 'Localizações'!$A$2:$D992, 4, FALSE), ""), "") -> https://imgur.com/a/ksXMwHN
A18: 10000 | B18: Ampharos | C18: Wild | D18: =IF(B18<>"", SWITCH(C18, "Wild", VLOOKUP(B18, 'Localizações'!$A$2:$D992, 2, FALSE), "Normal", VLOOKUP(B18, 'Localizações'!$A$2:$D992, 3, FALSE), "Hoenn", VLOOKUP(B18, 'Localizações'!$A$2:$D992, 4, FALSE), ""), "") -> https://imgur.com/a/O7GKc00 | E18: 3000
A19: 10000 | B19: Blastoise | C19: Wild | D19: =IF(B19<>"", SWITCH(C19, "Wild", VLOOKUP(B19, 'Localizações'!$A$2:$D992, 2, FALSE), "Normal", VLOOKUP(B19, 'Localizações'!$A$2:$D992, 3, FALSE), "Hoenn", VLOOKUP(B19, 'Localizações'!$A$2:$D992, 4, FALSE), ""), "") -> https://imgur.com/a/H98mIzg | E19: 2000
A20: 10000 | B20: Charizard | C20: Wild | D20: =IF(B20<>"", SWITCH(C20, "Wild", VLOOKUP(B20, 'Localizações'!$A$2:$D992, 2, FALSE), "Normal", VLOOKUP(B20, 'Localizações'!$A$2:$D992, 3, FALSE), "Hoenn", VLOOKUP(B20, 'Localizações'!$A$2:$D992, 4, FALSE), ""), "") -> https://imgur.com/a/thSWZiw | E20: 2500
A21: 10000 | B21: Dodrio | C21: Wild | D21: =IF(B21<>"", SWITCH(C21, "Wild", VLOOKUP(B21, 'Localizações'!$A$2:$D992, 2, FALSE), "Normal", VLOOKUP(B21, 'Localizações'!$A$2:$D992, 3, FALSE), "Hoenn", VLOOKUP(B21, 'Localizações'!$A$2:$D992, 4, FALSE), ""), "") -> https://imgur.com/a/mZdWvFw | E21: 2350
A22: 10000 | B22: Espeon | C22: Wild | D22: =IF(B22<>"", SWITCH(C22, "Wild", VLOOKUP(B22, 'Localizações'!$A$2:$D992, 2, FALSE), "Normal", VLOOKUP(B22, 'Localizações'!$A$2:$D992, 3, FALSE), "Hoenn", VLOOKUP(B22, 'Localizações'!$A$2:$D992, 4, FALSE), ""), "") -> https://imgur.com/a/CkBSqXN
A23: 10000 | B23: Farfetch'd | C23: Wild | D23: =IF(B23<>"", SWITCH(C23, "Wild", VLOOKUP(B23, 'Localizações'!$A$2:$D992, 2, FALSE), "Normal", VLOOKUP(B23, 'Localizações'!$A$2:$D992, 3, FALSE), "Hoenn", VLOOKUP(B23, 'Localizações'!$A$2:$D992, 4, FALSE), ""), "") -> https://imgur.com/a/mZdWvFw | E23: 2150
A24: 10000 | B24: Feraligatr | C24: Wild | D24: =IF(B24<>"", SWITCH(C24, "Wild", VLOOKUP(B24, 'Localizações'!$A$2:$D992, 2, FALSE), "Normal", VLOOKUP(B24, 'Localizações'!$A$2:$D992, 3, FALSE), "Hoenn", VLOOKUP(B24, 'Localizações'!$A$2:$D992, 4, FALSE), ""), "") -> https://imgur.com/a/H98mIzg | E24: 2700
A25: 10000 | B25: Flareon | C25: Wild | D25: =IF(B25<>"", SWITCH(C25, "Wild", VLOOKUP(B25, 'Localizações'!$A$2:$D992, 2, FALSE), "Normal", VLOOKUP(B25, 'Localizações'!$A$2:$D992, 3, FALSE), "Hoenn", VLOOKUP(B25, 'Localizações'!$A$2:$D992, 4, FALSE), ""), "") -> https://imgur.com/a/0QTUhoj | E25: 2500
A26: 10000 | B26: Golem | C26: Wild | D26: =IF(B26<>"", SWITCH(C26, "Wild", VLOOKUP(B26, 'Localizações'!$A$2:$D992, 2, FALSE), "Normal", VLOOKUP(B26, 'Localizações'!$A$2:$D992, 3, FALSE), "Hoenn", VLOOKUP(B26, 'Localizações'!$A$2:$D992, 4, FALSE), ""), "") -> https://imgur.com/a/rg5qYI4 | E26: 3150
A27: 10000 | B27: Hitmonchan | C27: Wild | D27: =IF(B27<>"", SWITCH(C27, "Wild", VLOOKUP(B27, 'Localizações'!$A$2:$D992, 2, FALSE), "Normal", VLOOKUP(B27, 'Localizações'!$A$2:$D992, 3, FALSE), "Hoenn", VLOOKUP(B27, 'Localizações'!$A$2:$D992, 4, FALSE), ""), "") -> https://imgur.com/a/pjIUv00
A28: 10000 | B28: Hitmonlee | C28: Wild | D28: =IF(B28<>"", SWITCH(C28, "Wild", VLOOKUP(B28, 'Localizações'!$A$2:$D992, 2, FALSE), "Normal", VLOOKUP(B28, 'Localizações'!$A$2:$D992, 3, FALSE), "Hoenn", VLOOKUP(B28, 'Localizações'!$A$2:$D992, 4, FALSE), ""), "") -> https://imgur.com/a/pjIUv00 | E28: 3300
A29: 10000 | B29: Hitmontop | C29: Wild | D29: =IF(B29<>"", SWITCH(C29, "Wild", VLOOKUP(B29, 'Localizações'!$A$2:$D992, 2, FALSE), "Normal", VLOOKUP(B29, 'Localizações'!$A$2:$D992, 3, FALSE), "Hoenn", VLOOKUP(B29, 'Localizações'!$A$2:$D992, 4, FALSE), ""), "") -> https://imgur.com/a/30cn4iq
A30: 10000 | B30: Jolteon | C30: Wild | D30: =IF(B30<>"", SWITCH(C30, "Wild", VLOOKUP(B30, 'Localizações'!$A$2:$D992, 2, FALSE), "Normal", VLOOKUP(B30, 'Localizações'!$A$2:$D992, 3, FALSE), "Hoenn", VLOOKUP(B30, 'Localizações'!$A$2:$D992, 4, FALSE), ""), "") -> https://imgur.com/a/clP3jSD
A31: 10000 | B31: Jynx | C31: Wild | D31: =IF(B31<>"", SWITCH(C31, "Wild", VLOOKUP(B31, 'Localizações'!$A$2:$D992, 2, FALSE), "Normal", VLOOKUP(B31, 'Localizações'!$A$2:$D992, 3, FALSE), "Hoenn", VLOOKUP(B31, 'Localizações'!$A$2:$D992, 4, FALSE), ""), "") -> https://imgur.com/a/3LppiO7 | E31: 3750
A32: 100 | B32: Kabutops | C32: Normal | D32: =IF(B32<>"", SWITCH(C32, "Wild", VLOOKUP(B32, 'Localizações'!$A$2:$D992, 2, FALSE), "Normal", VLOOKUP(B32, 'Localizações'!$A$2:$D992, 3, FALSE), "Hoenn", VLOOKUP(B32, 'Localizações'!$A$2:$D992, 4, FALSE), ""), "") -> https://imgur.com/a/hGRDfmM
A33: 10000 | B33: Lapras | C33: Wild | D33: =IF(B33<>"", SWITCH(C33, "Wild", VLOOKUP(B33, 'Localizações'!$A$2:$D992, 2, FALSE), "Normal", VLOOKUP(B33, 'Localizações'!$A$2:$D992, 3, FALSE), "Hoenn", VLOOKUP(B33, 'Localizações'!$A$2:$D992, 4, FALSE), ""), "") -> https://imgur.com/a/ca4NlMA
A34: 10000 | B34: Magcargo | C34: Wild | D34: =IF(B34<>"", SWITCH(C34, "Wild", VLOOKUP(B34, 'Localizações'!$A$2:$D992, 2, FALSE), "Normal", VLOOKUP(B34, 'Localizações'!$A$2:$D992, 3, FALSE), "Hoenn", VLOOKUP(B34, 'Localizações'!$A$2:$D992, 4, FALSE), ""), "") -> https://imgur.com/a/PjJgh5m
A35: 10000 | B35: Mantine | C35: Wild | D35: =IF(B35<>"", SWITCH(C35, "Wild", VLOOKUP(B35, 'Localizações'!$A$2:$D992, 2, FALSE), "Normal", VLOOKUP(B35, 'Localizações'!$A$2:$D992, 3, FALSE), "Hoenn", VLOOKUP(B35, 'Localizações'!$A$2:$D992, 4, FALSE), ""), "") -> https://imgur.com/a/H98mIzg | E35: 2750
A36: 10000 | B36: Marowak | C36: Wild | D36: =IF(B36<>"", SWITCH(C36, "Wild", VLOOKUP(B36, 'Localizações'!$A$2:$D992, 2, FALSE), "Normal", VLOOKUP(B36, 'Localizações'!$A$2:$D992, 3, FALSE), "Hoenn", VLOOKUP(B36, 'Localizações'!$A$2:$D992, 4, FALSE), ""), "") -> https://imgur.com/a/AYaHOY2
A37: 10000 | B37: Meganium | C37: Wild | D37: =IF(B37<>"", SWITCH(C37, "Wild", VLOOKUP(B37, 'Localizações'!$A$2:$D992, 2, FALSE), "Normal", VLOOKUP(B37, 'Localizações'!$A$2:$D992, 3, FALSE), "Hoenn", VLOOKUP(B37, 'Localizações'!$A$2:$D992, 4, FALSE), ""), "") -> https://imgur.com/uw0XICj | E37: 2100
A38: 10000 | B38: Miltank | C38: Wild | D38: =IF(B38<>"", SWITCH(C38, "Wild", VLOOKUP(B38, 'Localizações'!$A$2:$D992, 2, FALSE), "Normal", VLOOKUP(B38, 'Localizações'!$A$2:$D992, 3, FALSE), "Hoenn", VLOOKUP(B38, 'Localizações'!$A$2:$D992, 4, FALSE), ""), "") -> https://imgur.com/a/doQnA6i
A39: 10000 | B39: Muk | C39: Wild | D39: =IF(B39<>"", SWITCH(C39, "Wild", VLOOKUP(B39, 'Localizações'!$A$2:$D992, 2, FALSE), "Normal", VLOOKUP(B39, 'Localizações'!$A$2:$D992, 3, FALSE), "Hoenn", VLOOKUP(B39, 'Localizações'!$A$2:$D992, 4, FALSE), ""), "") -> https://imgur.com/a/vgGrrfT | E39: 2400
A40: 10000 | B40: Nidoking | C40: Wild | D40: =IF(B40<>"", SWITCH(C40, "Wild", VLOOKUP(B40, 'Localizações'!$A$2:$D992, 2, FALSE), "Normal", VLOOKUP(B40, 'Localizações'!$A$2:$D992, 3, FALSE), "Hoenn", VLOOKUP(B40, 'Localizações'!$A$2:$D992, 4, FALSE), ""), "") -> https://imgur.com/a/HWxtEs3 | E40: 2300
...

Sheet Localizações
A1: =IFERROR(__xludf.DUMMYFUNCTION("IMPORTRANGE(""https://docs.google.com/spreadsheets/d/1ID3qu1P4Zey82OSLntg4O0xoZlY1hGK58tte0D_Cv_s/edit?pli=1&gid=305783725#gid=305783725"",""Locations!A1:D1002"")"),"Pokémon") -> Pokémon | B1: =IFERROR(__xludf.DUMMYFUNCTION("""COMPUTED_VALUE"""),"Wildscape (Lvl 150+)") -> Wildscape (Lvl 150+) | C1: =IFERROR(__xludf.DUMMYFUNCTION("""COMPUTED_VALUE"""),"Normal") -> Normal | D1: =IFERROR(__xludf.DUMMYFUNCTION("""COMPUTED_VALUE"""),"Hoenn (Lvl 250+)") -> Hoenn (Lvl 250+)
A2: =IFERROR(__xludf.DUMMYFUNCTION("""COMPUTED_VALUE"""),"Bulbasaur") -> Bulbasaur | B2: =IFERROR(__xludf.DUMMYFUNCTION("""COMPUTED_VALUE"""),"-") -> - | C2: =IFERROR(__xludf.DUMMYFUNCTION("""COMPUTED_VALUE"""),"https://imgur.com/a/jcpzOgr") -> https://imgur.com/a/jcpzOgr | D2: =IFERROR(__xludf.DUMMYFUNCTION("""COMPUTED_VALUE"""),"-") -> - | E2: Como usar - Aperte Ctrl+F - Pesquise o nome do Pokémon que quer caçar Ilhas Laranja: https://imgur.com/a/FV42d75 Hoenn: https://imgur.com/a/Uwf1wBW
A3: =IFERROR(__xludf.DUMMYFUNCTION("""COMPUTED_VALUE"""),"Ivysaur") -> Ivysaur | B3: =IFERROR(__xludf.DUMMYFUNCTION("""COMPUTED_VALUE"""),"-") -> - | C3: =IFERROR(__xludf.DUMMYFUNCTION("""COMPUTED_VALUE"""),"https://imgur.com/a/XEfXuD8") -> https://imgur.com/a/XEfXuD8 | D3: =IFERROR(__xludf.DUMMYFUNCTION("""COMPUTED_VALUE"""),"-") -> -
A4: =IFERROR(__xludf.DUMMYFUNCTION("""COMPUTED_VALUE"""),"Venusaur") -> Venusaur | B4: =IFERROR(__xludf.DUMMYFUNCTION("""COMPUTED_VALUE"""),"https://imgur.com/a/QZY9tMI") -> https://imgur.com/a/QZY9tMI | C4: =IFERROR(__xludf.DUMMYFUNCTION("""COMPUTED_VALUE"""),"https://imgur.com/a/zRcrSLP") -> https://imgur.com/a/zRcrSLP | D4: =IFERROR(__xludf.DUMMYFUNCTION("""COMPUTED_VALUE"""),"-") -> -
A5: =IFERROR(__xludf.DUMMYFUNCTION("""COMPUTED_VALUE"""),"Charmander") -> Charmander | B5: =IFERROR(__xludf.DUMMYFUNCTION("""COMPUTED_VALUE"""),"-") -> - | C5: =IFERROR(__xludf.DUMMYFUNCTION("""COMPUTED_VALUE"""),"https://imgur.com/a/8vGvdYp") -> https://imgur.com/a/8vGvdYp | D5: =IFERROR(__xludf.DUMMYFUNCTION("""COMPUTED_VALUE"""),"-") -> -
A6: =IFERROR(__xludf.DUMMYFUNCTION("""COMPUTED_VALUE"""),"Charmelion") -> Charmelion | B6: =IFERROR(__xludf.DUMMYFUNCTION("""COMPUTED_VALUE"""),"-") -> - | C6: =IFERROR(__xludf.DUMMYFUNCTION("""COMPUTED_VALUE"""),"https://imgur.com/a/5ZdzM08") -> https://imgur.com/a/5ZdzM08 | D6: =IFERROR(__xludf.DUMMYFUNCTION("""COMPUTED_VALUE"""),"-") -> -
A7: =IFERROR(__xludf.DUMMYFUNCTION("""COMPUTED_VALUE"""),"Charizard") -> Charizard | B7: =IFERROR(__xludf.DUMMYFUNCTION("""COMPUTED_VALUE"""),"https://imgur.com/a/thSWZiw") -> https://imgur.com/a/thSWZiw | C7: =IFERROR(__xludf.DUMMYFUNCTION("""COMPUTED_VALUE"""),"https://imgur.com/a/ksXMwHN") -> https://imgur.com/a/ksXMwHN | D7: =IFERROR(__xludf.DUMMYFUNCTION("""COMPUTED_VALUE"""),"-") -> -
A8: =IFERROR(__xludf.DUMMYFUNCTION("""COMPUTED_VALUE"""),"Squirtle") -> Squirtle | B8: =IFERROR(__xludf.DUMMYFUNCTION("""COMPUTED_VALUE"""),"-") -> - | C8: =IFERROR(__xludf.DUMMYFUNCTION("""COMPUTED_VALUE"""),"https://imgur.com/a/8ZPHQzh") -> https://imgur.com/a/8ZPHQzh | D8: =IFERROR(__xludf.DUMMYFUNCTION("""COMPUTED_VALUE"""),"-") -> -
A9: =IFERROR(__xludf.DUMMYFUNCTION("""COMPUTED_VALUE"""),"Wartortle") -> Wartortle | B9: =IFERROR(__xludf.DUMMYFUNCTION("""COMPUTED_VALUE"""),"-") -> - | C9: =IFERROR(__xludf.DUMMYFUNCTION("""COMPUTED_VALUE"""),"https://imgur.com/a/wXrfm6F") -> https://imgur.com/a/wXrfm6F | D9: =IFERROR(__xludf.DUMMYFUNCTION("""COMPUTED_VALUE"""),"-") -> -
A10: =IFERROR(__xludf.DUMMYFUNCTION("""COMPUTED_VALUE"""),"Blastoise") -> Blastoise | B10: =IFERROR(__xludf.DUMMYFUNCTION("""COMPUTED_VALUE"""),"https://imgur.com/a/H98mIzg") -> https://imgur.com/a/H98mIzg | C10: =IFERROR(__xludf.DUMMYFUNCTION("""COMPUTED_VALUE"""),"https://imgur.com/a/o6O5mnt") -> https://imgur.com/a/o6O5mnt | D10: =IFERROR(__xludf.DUMMYFUNCTION("""COMPUTED_VALUE"""),"-") -> -
A11: =IFERROR(__xludf.DUMMYFUNCTION("""COMPUTED_VALUE"""),"Caterpie") -> Caterpie | B11: =IFERROR(__xludf.DUMMYFUNCTION("""COMPUTED_VALUE"""),"-") -> - | C11: =IFERROR(__xludf.DUMMYFUNCTION("""COMPUTED_VALUE"""),"https://imgur.com/a/FRZPc0L") -> https://imgur.com/a/FRZPc0L | D11: =IFERROR(__xludf.DUMMYFUNCTION("""COMPUTED_VALUE"""),"-") -> -
A12: =IFERROR(__xludf.DUMMYFUNCTION("""COMPUTED_VALUE"""),"Metapod") -> Metapod | B12: =IFERROR(__xludf.DUMMYFUNCTION("""COMPUTED_VALUE"""),"-") -> - | C12: =IFERROR(__xludf.DUMMYFUNCTION("""COMPUTED_VALUE"""),"https://imgur.com/a/Md3zxUt") -> https://imgur.com/a/Md3zxUt | D12: =IFERROR(__xludf.DUMMYFUNCTION("""COMPUTED_VALUE"""),"-") -> -
A13: =IFERROR(__xludf.DUMMYFUNCTION("""COMPUTED_VALUE"""),"Butterfree") -> Butterfree | B13: =IFERROR(__xludf.DUMMYFUNCTION("""COMPUTED_VALUE"""),"-") -> - | C13: =IFERROR(__xludf.DUMMYFUNCTION("""COMPUTED_VALUE"""),"https://imgur.com/a/IAhK3th") -> https://imgur.com/a/IAhK3th | D13: =IFERROR(__xludf.DUMMYFUNCTION("""COMPUTED_VALUE"""),"-") -> -
A14: =IFERROR(__xludf.DUMMYFUNCTION("""COMPUTED_VALUE"""),"Weedle") -> Weedle | B14: =IFERROR(__xludf.DUMMYFUNCTION("""COMPUTED_VALUE"""),"-") -> - | C14: =IFERROR(__xludf.DUMMYFUNCTION("""COMPUTED_VALUE"""),"https://imgur.com/a/3UGhQN6") -> https://imgur.com/a/3UGhQN6 | D14: =IFERROR(__xludf.DUMMYFUNCTION("""COMPUTED_VALUE"""),"-") -> -
A15: =IFERROR(__xludf.DUMMYFUNCTION("""COMPUTED_VALUE"""),"Kakuna") -> Kakuna | B15: =IFERROR(__xludf.DUMMYFUNCTION("""COMPUTED_VALUE"""),"-") -> - | C15: =IFERROR(__xludf.DUMMYFUNCTION("""COMPUTED_VALUE"""),"https://imgur.com/a/u3FmFya") -> https://imgur.com/a/u3FmFya | D15: =IFERROR(__xludf.DUMMYFUNCTION("""COMPUTED_VALUE"""),"-") -> -
A16: =IFERROR(__xludf.DUMMYFUNCTION("""COMPUTED_VALUE"""),"Beedrill") -> Beedrill | B16: =IFERROR(__xludf.DUMMYFUNCTION("""COMPUTED_VALUE"""),"-") -> - | C16: =IFERROR(__xludf.DUMMYFUNCTION("""COMPUTED_VALUE"""),"https://imgur.com/a/1F8OZPT") -> https://imgur.com/a/1F8OZPT | D16: =IFERROR(__xludf.DUMMYFUNCTION("""COMPUTED_VALUE"""),"-") -> -
A17: =IFERROR(__xludf.DUMMYFUNCTION("""COMPUTED_VALUE"""),"Pidgey") -> Pidgey | B17: =IFERROR(__xludf.DUMMYFUNCTION("""COMPUTED_VALUE"""),"-") -> - | C17: =IFERROR(__xludf.DUMMYFUNCTION("""COMPUTED_VALUE"""),"https://imgur.com/a/ANHSsgY") -> https://imgur.com/a/ANHSsgY | D17: =IFERROR(__xludf.DUMMYFUNCTION("""COMPUTED_VALUE"""),"-") -> -
A18: =IFERROR(__xludf.DUMMYFUNCTION("""COMPUTED_VALUE"""),"Pidgeotto") -> Pidgeotto | B18: =IFERROR(__xludf.DUMMYFUNCTION("""COMPUTED_VALUE"""),"-") -> - | C18: =IFERROR(__xludf.DUMMYFUNCTION("""COMPUTED_VALUE"""),"https://imgur.com/a/yq5WqUg") -> https://imgur.com/a/yq5WqUg | D18: =IFERROR(__xludf.DUMMYFUNCTION("""COMPUTED_VALUE"""),"-") -> -
A19: =IFERROR(__xludf.DUMMYFUNCTION("""COMPUTED_VALUE"""),"Pidgeot") -> Pidgeot | B19: =IFERROR(__xludf.DUMMYFUNCTION("""COMPUTED_VALUE"""),"https://imgur.com/a/mZdWvFw") -> https://imgur.com/a/mZdWvFw | C19: =IFERROR(__xludf.DUMMYFUNCTION("""COMPUTED_VALUE"""),"https://imgur.com/a/SmDawr1") -> https://imgur.com/a/SmDawr1 | D19: =IFERROR(__xludf.DUMMYFUNCTION("""COMPUTED_VALUE"""),"-") -> -
A20: =IFERROR(__xludf.DUMMYFUNCTION("""COMPUTED_VALUE"""),"Rattata") -> Rattata | B20: =IFERROR(__xludf.DUMMYFUNCTION("""COMPUTED_VALUE"""),"-") -> - | C20: =IFERROR(__xludf.DUMMYFUNCTION("""COMPUTED_VALUE"""),"https://imgur.com/a/ZyszZOZ") -> https://imgur.com/a/ZyszZOZ | D20: =IFERROR(__xludf.DUMMYFUNCTION("""COMPUTED_VALUE"""),"-") -> -
A21: =IFERROR(__xludf.DUMMYFUNCTION("""COMPUTED_VALUE"""),"Raticate") -> Raticate | B21: =IFERROR(__xludf.DUMMYFUNCTION("""COMPUTED_VALUE"""),"-") -> - | C21: =IFERROR(__xludf.DUMMYFUNCTION("""COMPUTED_VALUE"""),"https://imgur.com/a/ZyszZOZ") -> https://imgur.com/a/ZyszZOZ | D21: =IFERROR(__xludf.DUMMYFUNCTION("""COMPUTED_VALUE"""),"-") -> -
A22: =IFERROR(__xludf.DUMMYFUNCTION("""COMPUTED_VALUE"""),"Spearow") -> Spearow | B22: =IFERROR(__xludf.DUMMYFUNCTION("""COMPUTED_VALUE"""),"-") -> - | C22: =IFERROR(__xludf.DUMMYFUNCTION("""COMPUTED_VALUE"""),"https://imgur.com/a/ANHSsgY") -> https://imgur.com/a/ANHSsgY | D22: =IFERROR(__xludf.DUMMYFUNCTION("""COMPUTED_VALUE"""),"-") -> -
A23: =IFERROR(__xludf.DUMMYFUNCTION("""COMPUTED_VALUE"""),"Fearow") -> Fearow | B23: =IFERROR(__xludf.DUMMYFUNCTION("""COMPUTED_VALUE"""),"-") -> - | C23: =IFERROR(__xludf.DUMMYFUNCTION("""COMPUTED_VALUE"""),"https://imgur.com/a/NVXqWOp") -> https://imgur.com/a/NVXqWOp | D23: =IFERROR(__xludf.DUMMYFUNCTION("""COMPUTED_VALUE"""),"-") -> -
A24: =IFERROR(__xludf.DUMMYFUNCTION("""COMPUTED_VALUE"""),"Ekans") -> Ekans | B24: =IFERROR(__xludf.DUMMYFUNCTION("""COMPUTED_VALUE"""),"-") -> - | C24: =IFERROR(__xludf.DUMMYFUNCTION("""COMPUTED_VALUE"""),"https://imgur.com/a/X7pm0Qb") -> https://imgur.com/a/X7pm0Qb | D24: =IFERROR(__xludf.DUMMYFUNCTION("""COMPUTED_VALUE"""),"-") -> -
A25: =IFERROR(__xludf.DUMMYFUNCTION("""COMPUTED_VALUE"""),"Arbok") -> Arbok | B25: =IFERROR(__xludf.DUMMYFUNCTION("""COMPUTED_VALUE"""),"-") -> - | C25: =IFERROR(__xludf.DUMMYFUNCTION("""COMPUTED_VALUE"""),"https://imgur.com/a/urtC1Gz") -> https://imgur.com/a/urtC1Gz | D25: =IFERROR(__xludf.DUMMYFUNCTION("""COMPUTED_VALUE"""),"-") -> -
A26: =IFERROR(__xludf.DUMMYFUNCTION("""COMPUTED_VALUE"""),"Pikachu") -> Pikachu | B26: =IFERROR(__xludf.DUMMYFUNCTION("""COMPUTED_VALUE"""),"-") -> - | C26: =IFERROR(__xludf.DUMMYFUNCTION("""COMPUTED_VALUE"""),"https://imgur.com/a/eMjPulX") -> https://imgur.com/a/eMjPulX | D26: =IFERROR(__xludf.DUMMYFUNCTION("""COMPUTED_VALUE"""),"-") -> -
A27: =IFERROR(__xludf.DUMMYFUNCTION("""COMPUTED_VALUE"""),"Raichu") -> Raichu | B27: =IFERROR(__xludf.DUMMYFUNCTION("""COMPUTED_VALUE"""),"https://imgur.com/a/clP3jSD") -> https://imgur.com/a/clP3jSD | C27: =IFERROR(__xludf.DUMMYFUNCTION("""COMPUTED_VALUE"""),"https://imgur.com/a/tVt9b2v") -> https://imgur.com/a/tVt9b2v | D27: =IFERROR(__xludf.DUMMYFUNCTION("""COMPUTED_VALUE"""),"-") -> -
A28: =IFERROR(__xludf.DUMMYFUNCTION("""COMPUTED_VALUE"""),"Sandshrew") -> Sandshrew | B28: =IFERROR(__xludf.DUMMYFUNCTION("""COMPUTED_VALUE"""),"-") -> - | C28: =IFERROR(__xludf.DUMMYFUNCTION("""COMPUTED_VALUE"""),"https://imgur.com/a/hqHxs3c") -> https://imgur.com/a/hqHxs3c | D28: =IFERROR(__xludf.DUMMYFUNCTION("""COMPUTED_VALUE"""),"-") -> -
A29: =IFERROR(__xludf.DUMMYFUNCTION("""COMPUTED_VALUE"""),"Sandslash") -> Sandslash | B29: =IFERROR(__xludf.DUMMYFUNCTION("""COMPUTED_VALUE"""),"https://imgur.com/a/d4z4t8M") -> https://imgur.com/a/d4z4t8M | C29: =IFERROR(__xludf.DUMMYFUNCTION("""COMPUTED_VALUE"""),"https://imgur.com/a/jyNtIqk") -> https://imgur.com/a/jyNtIqk | D29: =IFERROR(__xludf.DUMMYFUNCTION("""COMPUTED_VALUE"""),"-") -> -
A30: =IFERROR(__xludf.DUMMYFUNCTION("""COMPUTED_VALUE"""),"Nidoran female") -> Nidoran female | B30: =IFERROR(__xludf.DUMMYFUNCTION("""COMPUTED_VALUE"""),"-") -> - | C30: =IFERROR(__xludf.DUMMYFUNCTION("""COMPUTED_VALUE"""),"https://imgur.com/a/fZJqgPy") -> https://imgur.com/a/fZJqgPy | D30: =IFERROR(__xludf.DUMMYFUNCTION("""COMPUTED_VALUE"""),"-") -> -
A31: =IFERROR(__xludf.DUMMYFUNCTION("""COMPUTED_VALUE"""),"Nidorina") -> Nidorina | B31: =IFERROR(__xludf.DUMMYFUNCTION("""COMPUTED_VALUE"""),"-") -> - | C31: =IFERROR(__xludf.DUMMYFUNCTION("""COMPUTED_VALUE"""),"https://imgur.com/a/x0itz9y") -> https://imgur.com/a/x0itz9y | D31: =IFERROR(__xludf.DUMMYFUNCTION("""COMPUTED_VALUE"""),"-") -> -
A32: =IFERROR(__xludf.DUMMYFUNCTION("""COMPUTED_VALUE"""),"Nidoqueen") -> Nidoqueen | B32: =IFERROR(__xludf.DUMMYFUNCTION("""COMPUTED_VALUE"""),"https://imgur.com/a/lnONjUq") -> https://imgur.com/a/lnONjUq | C32: =IFERROR(__xludf.DUMMYFUNCTION("""COMPUTED_VALUE"""),"https://imgur.com/a/UiIeSQX") -> https://imgur.com/a/UiIeSQX | D32: =IFERROR(__xludf.DUMMYFUNCTION("""COMPUTED_VALUE"""),"-") -> -
A33: =IFERROR(__xludf.DUMMYFUNCTION("""COMPUTED_VALUE"""),"Nidoran Male") -> Nidoran Male | B33: =IFERROR(__xludf.DUMMYFUNCTION("""COMPUTED_VALUE"""),"-") -> - | C33: =IFERROR(__xludf.DUMMYFUNCTION("""COMPUTED_VALUE"""),"https://imgur.com/a/fZJqgPy") -> https://imgur.com/a/fZJqgPy | D33: =IFERROR(__xludf.DUMMYFUNCTION("""COMPUTED_VALUE"""),"-") -> -
A34: =IFERROR(__xludf.DUMMYFUNCTION("""COMPUTED_VALUE"""),"Nidorino") -> Nidorino | B34: =IFERROR(__xludf.DUMMYFUNCTION("""COMPUTED_VALUE"""),"-") -> - | C34: =IFERROR(__xludf.DUMMYFUNCTION("""COMPUTED_VALUE"""),"https://imgur.com/a/x0itz9y") -> https://imgur.com/a/x0itz9y | D34: =IFERROR(__xludf.DUMMYFUNCTION("""COMPUTED_VALUE"""),"-") -> -
A35: =IFERROR(__xludf.DUMMYFUNCTION("""COMPUTED_VALUE"""),"Nidoking") -> Nidoking | B35: =IFERROR(__xludf.DUMMYFUNCTION("""COMPUTED_VALUE"""),"https://imgur.com/a/HWxtEs3") -> https://imgur.com/a/HWxtEs3 | C35: =IFERROR(__xludf.DUMMYFUNCTION("""COMPUTED_VALUE"""),"https://imgur.com/a/6fIH7lZ") -> https://imgur.com/a/6fIH7lZ | D35: =IFERROR(__xludf.DUMMYFUNCTION("""COMPUTED_VALUE"""),"-") -> -
A36: =IFERROR(__xludf.DUMMYFUNCTION("""COMPUTED_VALUE"""),"Clefairy") -> Clefairy | B36: =IFERROR(__xludf.DUMMYFUNCTION("""COMPUTED_VALUE"""),"-") -> - | C36: =IFERROR(__xludf.DUMMYFUNCTION("""COMPUTED_VALUE"""),"https://imgur.com/a/HipDvE8") -> https://imgur.com/a/HipDvE8 | D36: =IFERROR(__xludf.DUMMYFUNCTION("""COMPUTED_VALUE"""),"-") -> -
A37: =IFERROR(__xludf.DUMMYFUNCTION("""COMPUTED_VALUE"""),"Clefable") -> Clefable | B37: =IFERROR(__xludf.DUMMYFUNCTION("""COMPUTED_VALUE"""),"https://imgur.com/a/sXQlso1") -> https://imgur.com/a/sXQlso1 | C37: =IFERROR(__xludf.DUMMYFUNCTION("""COMPUTED_VALUE"""),"Escada na DG de Floette em Pewter") -> Escada na DG de Floette em Pewter | D37: =IFERROR(__xludf.DUMMYFUNCTION("""COMPUTED_VALUE"""),"-") -> -
A38: =IFERROR(__xludf.DUMMYFUNCTION("""COMPUTED_VALUE"""),"Vulpix") -> Vulpix | B38: =IFERROR(__xludf.DUMMYFUNCTION("""COMPUTED_VALUE"""),"-") -> - | C38: =IFERROR(__xludf.DUMMYFUNCTION("""COMPUTED_VALUE"""),"https://imgur.com/a/G4NlFHG") -> https://imgur.com/a/G4NlFHG | D38: =IFERROR(__xludf.DUMMYFUNCTION("""COMPUTED_VALUE"""),"-") -> -
A39: =IFERROR(__xludf.DUMMYFUNCTION("""COMPUTED_VALUE"""),"Ninetales") -> Ninetales | B39: =IFERROR(__xludf.DUMMYFUNCTION("""COMPUTED_VALUE"""),"https://imgur.com/a/2uMZqFZ") -> https://imgur.com/a/2uMZqFZ | C39: =IFERROR(__xludf.DUMMYFUNCTION("""COMPUTED_VALUE"""),"https://imgur.com/a/Rh21XkV") -> https://imgur.com/a/Rh21XkV | D39: =IFERROR(__xludf.DUMMYFUNCTION("""COMPUTED_VALUE"""),"-") -> -
A40: =IFERROR(__xludf.DUMMYFUNCTION("""COMPUTED_VALUE"""),"Jigglypuff") -> Jigglypuff | B40: =IFERROR(__xludf.DUMMYFUNCTION("""COMPUTED_VALUE"""),"-") -> - | C40: =IFERROR(__xludf.DUMMYFUNCTION("""COMPUTED_VALUE"""),"https://imgur.com/a/HipDvE8") -> https://imgur.com/a/HipDvE8 | D40: =IFERROR(__xludf.DUMMYFUNCTION("""COMPUTED_VALUE"""),"-") -> -
...

Sheet Search
A1: ITEM | C1: ="Pokemons que dropam '" & A2 & "'" -> Pokemons que dropam 'bottle of poison' | D1: Como usar - Pesquise o Item na célula A2 (clique no dropdown e digite o nome) - Os pokemons aparecerão na coluna C - Por uma limitação do Google, se tiver muita gente (90+ pessoas) usando a planilha, o campo de pesquisa não pode ser editado. Se isso acontecer, use essa planilha: Copy of Pokedex pública - Pokemon alliance (By Mts Vitor)
A2: bottle of poison | C2: =IFERROR(__xludf.DUMMYFUNCTION("FILTER(Drops!A:A, (Drops!B:B=A2) + (Drops!C:C=A2) + (Drops!D:D=A2) + (Drops!E:E=A2) + (Drops!F:F=A2) + (Drops!G:G=A2) + (Drops!H:H=A2) + (Drops!I:I=A2) + (Drops!J:J=A2) + (Drops!K:K=A2))"),"Bulbasaur") -> Bulbasaur
C3: =IFERROR(__xludf.DUMMYFUNCTION("""COMPUTED_VALUE"""),"Shiny Bulbasaur") -> Shiny Bulbasaur
C4: =IFERROR(__xludf.DUMMYFUNCTION("""COMPUTED_VALUE"""),"Ivysaur") -> Ivysaur
C5: =IFERROR(__xludf.DUMMYFUNCTION("""COMPUTED_VALUE"""),"Shiny Ivysaur") -> Shiny Ivysaur
C6: =IFERROR(__xludf.DUMMYFUNCTION("""COMPUTED_VALUE"""),"Venusaur") -> Venusaur
C7: =IFERROR(__xludf.DUMMYFUNCTION("""COMPUTED_VALUE"""),"Shiny Venusaur") -> Shiny Venusaur
C8: =IFERROR(__xludf.DUMMYFUNCTION("""COMPUTED_VALUE"""),"Weedle") -> Weedle
C9: =IFERROR(__xludf.DUMMYFUNCTION("""COMPUTED_VALUE"""),"Shiny Weedle") -> Shiny Weedle
C10: =IFERROR(__xludf.DUMMYFUNCTION("""COMPUTED_VALUE"""),"Kakuna") -> Kakuna
C11: =IFERROR(__xludf.DUMMYFUNCTION("""COMPUTED_VALUE"""),"Shiny Kakuna") -> Shiny Kakuna
C12: =IFERROR(__xludf.DUMMYFUNCTION("""COMPUTED_VALUE"""),"Beedrill") -> Beedrill
C13: =IFERROR(__xludf.DUMMYFUNCTION("""COMPUTED_VALUE"""),"Shiny Beedrill") -> Shiny Beedrill
C14: =IFERROR(__xludf.DUMMYFUNCTION("""COMPUTED_VALUE"""),"Ekans") -> Ekans
C15: =IFERROR(__xludf.DUMMYFUNCTION("""COMPUTED_VALUE"""),"Shiny Ekans") -> Shiny Ekans
C16: =IFERROR(__xludf.DUMMYFUNCTION("""COMPUTED_VALUE"""),"Arbok") -> Arbok
C17: =IFERROR(__xludf.DUMMYFUNCTION("""COMPUTED_VALUE"""),"Shiny Arbok") -> Shiny Arbok
C18: =IFERROR(__xludf.DUMMYFUNCTION("""COMPUTED_VALUE"""),"Nidoran female") -> Nidoran female
C19: =IFERROR(__xludf.DUMMYFUNCTION("""COMPUTED_VALUE"""),"Shiny Nidoran female") -> Shiny Nidoran female
C20: =IFERROR(__xludf.DUMMYFUNCTION("""COMPUTED_VALUE"""),"Nidorina") -> Nidorina
C21: =IFERROR(__xludf.DUMMYFUNCTION("""COMPUTED_VALUE"""),"Shiny Nidorina") -> Shiny Nidorina
C22: =IFERROR(__xludf.DUMMYFUNCTION("""COMPUTED_VALUE"""),"Nidoqueen") -> Nidoqueen
C23: =IFERROR(__xludf.DUMMYFUNCTION("""COMPUTED_VALUE"""),"Shiny Nidoqueen") -> Shiny Nidoqueen
C24: =IFERROR(__xludf.DUMMYFUNCTION("""COMPUTED_VALUE"""),"Nidoran Male") -> Nidoran Male
C25: =IFERROR(__xludf.DUMMYFUNCTION("""COMPUTED_VALUE"""),"Shiny Nidoran Male") -> Shiny Nidoran Male
C26: =IFERROR(__xludf.DUMMYFUNCTION("""COMPUTED_VALUE"""),"Nidorino") -> Nidorino
C27: =IFERROR(__xludf.DUMMYFUNCTION("""COMPUTED_VALUE"""),"Shiny Nidorino") -> Shiny Nidorino
C28: =IFERROR(__xludf.DUMMYFUNCTION("""COMPUTED_VALUE"""),"Nidoking") -> Nidoking
C29: =IFERROR(__xludf.DUMMYFUNCTION("""COMPUTED_VALUE"""),"Shiny Nidoking") -> Shiny Nidoking
C30: =IFERROR(__xludf.DUMMYFUNCTION("""COMPUTED_VALUE"""),"Zubat") -> Zubat
C31: =IFERROR(__xludf.DUMMYFUNCTION("""COMPUTED_VALUE"""),"Shiny Zubat") -> Shiny Zubat
C32: =IFERROR(__xludf.DUMMYFUNCTION("""COMPUTED_VALUE"""),"Golbat") -> Golbat
C33: =IFERROR(__xludf.DUMMYFUNCTION("""COMPUTED_VALUE"""),"Shiny Golbat") -> Shiny Golbat
C34: =IFERROR(__xludf.DUMMYFUNCTION("""COMPUTED_VALUE"""),"Oddish") -> Oddish
C35: =IFERROR(__xludf.DUMMYFUNCTION("""COMPUTED_VALUE"""),"Shiny Oddish") -> Shiny Oddish
C36: =IFERROR(__xludf.DUMMYFUNCTION("""COMPUTED_VALUE"""),"Gloom") -> Gloom
C37: =IFERROR(__xludf.DUMMYFUNCTION("""COMPUTED_VALUE"""),"Shiny Gloom") -> Shiny Gloom
C38: =IFERROR(__xludf.DUMMYFUNCTION("""COMPUTED_VALUE"""),"Vileplume") -> Vileplume
C39: =IFERROR(__xludf.DUMMYFUNCTION("""COMPUTED_VALUE"""),"Shiny Vileplume") -> Shiny Vileplume
C40: =IFERROR(__xludf.DUMMYFUNCTION("""COMPUTED_VALUE"""),"Venonat") -> Venonat
...

Sheet PokeTalents
A1: a | D1: Quantidade | E1: Tipo | F1: # | H1: Buff
A2: fighter hawk | B2: Machop | C2: =IF(A2<>"",A2&" ("&B2&")", "") -> fighter hawk (Machop) | D2: 25 | E2: Character | F2: 1 | G2: =IF(E2<>"", E2 & " #" & F2, "") -> Character #1 | H2: Gives all your Pokemon 1% critical chance. | I2: 1 - Gives all your Pokemon 1% critical chance.
A3: rock fist | B3: Geodude | C3: =IF(A3<>"",A3&" ("&B3&")", "") -> rock fist (Geodude) | D3: 25 | E3: Character | F3: 1 | G3: =IF(E3<>"", E3 & " #" & F3, "") -> Character #1 | H3: Gives all your Pokemon 1% critical chance. | I3: 1 - Gives all your Pokemon 1% critical chance.
A4: bear claw | B4: Ursaring | C4: =IF(A4<>"",A4&" ("&B4&")", "") -> bear claw (Ursaring) | D4: 1500 | E4: Character | F4: 2 | G4: =IF(E4<>"", E4 & " #" & F4, "") -> Character #2 | H4: Accelerates the regeneration of 1 second cooldown of the spells of Pokemon stored in the bag (Pokemon that remain inside the Poke Balls). | I4: 2 - Accelerates the regeneration of 1 second cooldown of the spells of Pokemon stored in the bag (Pokemon that remain inside the Poke Balls).
A5: cow tail | B5: Miltank | C5: =IF(A5<>"",A5&" ("&B5&")", "") -> cow tail (Miltank) | D5: 1100 | E5: Character | F5: 2 | G5: =IF(E5<>"", E5 & " #" & F5, "") -> Character #2 | H5: Accelerates the regeneration of 1 second cooldown of the spells of Pokemon stored in the bag (Pokemon that remain inside the Poke Balls). | I5: 2 - Accelerates the regeneration of 1 second cooldown of the spells of Pokemon stored in the bag (Pokemon that remain inside the Poke Balls).
A6: earth badge | B6: Viridian Gym | C6: =IF(A6<>"",A6&" ("&B6&")", "") -> earth badge (Viridian Gym) | D6: 1 | E6: Character | F6: 2 | G6: =IF(E6<>"", E6 & " #" & F6, "") -> Character #2 | H6: Accelerates the regeneration of 1 second cooldown of the spells of Pokemon stored in the bag (Pokemon that remain inside the Poke Balls). | I6: 2 - Accelerates the regeneration of 1 second cooldown of the spells of Pokemon stored in the bag (Pokemon that remain inside the Poke Balls).
A7: heart stone | C7: =IF(A7<>"",A7&" ("&B7&")", "") -> heart stone () | D7: 1000 | E7: Character | F7: 2 | G7: =IF(E7<>"", E7 & " #" & F7, "") -> Character #2 | H7: Accelerates the regeneration of 1 second cooldown of the spells of Pokemon stored in the bag (Pokemon that remain inside the Poke Balls). | I7: 2 - Accelerates the regeneration of 1 second cooldown of the spells of Pokemon stored in the bag (Pokemon that remain inside the Poke Balls).
A8: pink wings | B8: Clefable | C8: =IF(A8<>"",A8&" ("&B8&")", "") -> pink wings (Clefable) | D8: 450 | E8: Character | F8: 2 | G8: =IF(E8<>"", E8 & " #" & F8, "") -> Character #2 | H8: Accelerates the regeneration of 1 second cooldown of the spells of Pokemon stored in the bag (Pokemon that remain inside the Poke Balls). | I8: 2 - Accelerates the regeneration of 1 second cooldown of the spells of Pokemon stored in the bag (Pokemon that remain inside the Poke Balls).
